Traceback (most recent call last):
  File "/home/ryan/miniconda3/envs/nbdev/lib/python3.10/site-packages/jupyter_cache/executors/utils.py", line 58, in single_nb_execution
    executenb(
  File "/home/ryan/miniconda3/envs/nbdev/lib/python3.10/site-packages/nbclient/client.py", line 1305, in execute
    return NotebookClient(nb=nb, resources=resources, km=km, **kwargs).execute()
  File "/home/ryan/miniconda3/envs/nbdev/lib/python3.10/site-packages/jupyter_core/utils/__init__.py", line 173, in wrapped
    return loop.run_until_complete(inner)
  File "/home/ryan/miniconda3/envs/nbdev/lib/python3.10/asyncio/base_events.py", line 649, in run_until_complete
    return future.result()
  File "/home/ryan/miniconda3/envs/nbdev/lib/python3.10/site-packages/nbclient/client.py", line 705, in async_execute
    await self.async_execute_cell(
  File "/home/ryan/miniconda3/envs/nbdev/lib/python3.10/site-packages/nbclient/client.py", line 1058, in async_execute_cell
    await self._check_raise_for_error(cell, cell_index, exec_reply)
  File "/home/ryan/miniconda3/envs/nbdev/lib/python3.10/site-packages/nbclient/client.py", line 914, in _check_raise_for_error
    raise CellExecutionError.from_cell_and_msg(cell, exec_reply_content)
nbclient.exceptions.CellExecutionError: An error occurred while executing the following cell:
------------------
accel_data[i1:i2, :].shape
------------------


[0;31m---------------------------------------------------------------------------[0m
[0;31mNameError[0m                                 Traceback (most recent call last)
Cell [0;32mIn[7], line 1[0m
[0;32m----> 1[0m accel_data[[43mi1[49m:i2, :][38;5;241m.[39mshape

[0;31mNameError[0m: name 'i1' is not defined

